Workbook

Sheet Summary
A1: Summary
A2: All figures are formulas over the Test Cases sheet.
A4: Module | B4: Total | C4: P1 (release gate) | D4: P2 | E4: P3 | F4: Smoke | G4: Seeded-defect checks | H4: Automated | I4: Blocked | J4: Sensitive
A5: Authentication & Session | B5: =COUNTIF('Test Cases'!$C$5:$C$110,A5) | C5: =COUNTIFS('Test Cases'!$C$5:$C$110,A5,'Test Cases'!$P$5:$P$110,"P1") | D5: =COUNTIFS('Test Cases'!$C$5:$C$110,A5,'Test Cases'!$P$5:$P$110,"P2") | E5: =COUNTIFS('Test Cases'!$C$5:$C$110,A5,'Test Cases'!$P$5:$P$110,"P3") | F5: =COUNTIFS('Test Cases'!$C$5:$C$110,A5,'Test Cases'!$S$5:$S$110,"Y") | G5: =COUNTIFS('Test Cases'!$C$5:$C$110,A5,'Test Cases'!$G$5:$G$110,"?*") | H5: =COUNTIFS('Test Cases'!$C$5:$C$110,A5,'Test Cases'!$V$5:$V$110,"Automated") | I5: =COUNTIFS('Test Cases'!$C$5:$C$110,A5,'Test Cases'!$V$5:$V$110,"Blocked") | J5: =COUNTIFS('Test Cases'!$C$5:$C$110,A5,'Test Cases'!$T$5:$T$110,"Y")
A6: Agent Dashboard | B6: =COUNTIF('Test Cases'!$C$5:$C$110,A6) | C6: =COUNTIFS('Test Cases'!$C$5:$C$110,A6,'Test Cases'!$P$5:$P$110,"P1") | D6: =COUNTIFS('Test Cases'!$C$5:$C$110,A6,'Test Cases'!$P$5:$P$110,"P2") | E6: =COUNTIFS('Test Cases'!$C$5:$C$110,A6,'Test Cases'!$P$5:$P$110,"P3") | F6: =COUNTIFS('Test Cases'!$C$5:$C$110,A6,'Test Cases'!$S$5:$S$110,"Y") | G6: =COUNTIFS('Test Cases'!$C$5:$C$110,A6,'Test Cases'!$G$5:$G$110,"?*") | H6: =COUNTIFS('Test Cases'!$C$5:$C$110,A6,'Test Cases'!$V$5:$V$110,"Automated") | I6: =COUNTIFS('Test Cases'!$C$5:$C$110,A6,'Test Cases'!$V$5:$V$110,"Blocked") | J6: =COUNTIFS('Test Cases'!$C$5:$C$110,A6,'Test Cases'!$T$5:$T$110,"Y")
A7: Client / Insured Information | B7: =COUNTIF('Test Cases'!$C$5:$C$110,A7) | C7: =COUNTIFS('Test Cases'!$C$5:$C$110,A7,'Test Cases'!$P$5:$P$110,"P1") | D7: =COUNTIFS('Test Cases'!$C$5:$C$110,A7,'Test Cases'!$P$5:$P$110,"P2") | E7: =COUNTIFS('Test Cases'!$C$5:$C$110,A7,'Test Cases'!$P$5:$P$110,"P3") | F7: =COUNTIFS('Test Cases'!$C$5:$C$110,A7,'Test Cases'!$S$5:$S$110,"Y") | G7: =COUNTIFS('Test Cases'!$C$5:$C$110,A7,'Test Cases'!$G$5:$G$110,"?*") | H7: =COUNTIFS('Test Cases'!$C$5:$C$110,A7,'Test Cases'!$V$5:$V$110,"Automated") | I7: =COUNTIFS('Test Cases'!$C$5:$C$110,A7,'Test Cases'!$V$5:$V$110,"Blocked") | J7: =COUNTIFS('Test Cases'!$C$5:$C$110,A7,'Test Cases'!$T$5:$T$110,"Y")
A8: Product Selection & Policy Configuration | B8: =COUNTIF('Test Cases'!$C$5:$C$110,A8) | C8: =COUNTIFS('Test Cases'!$C$5:$C$110,A8,'Test Cases'!$P$5:$P$110,"P1") | D8: =COUNTIFS('Test Cases'!$C$5:$C$110,A8,'Test Cases'!$P$5:$P$110,"P2") | E8: =COUNTIFS('Test Cases'!$C$5:$C$110,A8,'Test Cases'!$P$5:$P$110,"P3") | F8: =COUNTIFS('Test Cases'!$C$5:$C$110,A8,'Test Cases'!$S$5:$S$110,"Y") | G8: =COUNTIFS('Test Cases'!$C$5:$C$110,A8,'Test Cases'!$G$5:$G$110,"?*") | H8: =COUNTIFS('Test Cases'!$C$5:$C$110,A8,'Test Cases'!$V$5:$V$110,"Automated") | I8: =COUNTIFS('Test Cases'!$C$5:$C$110,A8,'Test Cases'!$V$5:$V$110,"Blocked") | J8: =COUNTIFS('Test Cases'!$C$5:$C$110,A8,'Test Cases'!$T$5:$T$110,"Y")
A9: Rider Selection | B9: =COUNTIF('Test Cases'!$C$5:$C$110,A9) | C9: =COUNTIFS('Test Cases'!$C$5:$C$110,A9,'Test Cases'!$P$5:$P$110,"P1") | D9: =COUNTIFS('Test Cases'!$C$5:$C$110,A9,'Test Cases'!$P$5:$P$110,"P2") | E9: =COUNTIFS('Test Cases'!$C$5:$C$110,A9,'Test Cases'!$P$5:$P$110,"P3") | F9: =COUNTIFS('Test Cases'!$C$5:$C$110,A9,'Test Cases'!$S$5:$S$110,"Y") | G9: =COUNTIFS('Test Cases'!$C$5:$C$110,A9,'Test Cases'!$G$5:$G$110,"?*") | H9: =COUNTIFS('Test Cases'!$C$5:$C$110,A9,'Test Cases'!$V$5:$V$110,"Automated") | I9: =COUNTIFS('Test Cases'!$C$5:$C$110,A9,'Test Cases'!$V$5:$V$110,"Blocked") | J9: =COUNTIFS('Test Cases'!$C$5:$C$110,A9,'Test Cases'!$T$5:$T$110,"Y")
A10: Beneficiary Management | B10: =COUNTIF('Test Cases'!$C$5:$C$110,A10) | C10: =COUNTIFS('Test Cases'!$C$5:$C$110,A10,'Test Cases'!$P$5:$P$110,"P1") | D10: =COUNTIFS('Test Cases'!$C$5:$C$110,A10,'Test Cases'!$P$5:$P$110,"P2") | E10: =COUNTIFS('Test Cases'!$C$5:$C$110,A10,'Test Cases'!$P$5:$P$110,"P3") | F10: =COUNTIFS('Test Cases'!$C$5:$C$110,A10,'Test Cases'!$S$5:$S$110,"Y") | G10: =COUNTIFS('Test Cases'!$C$5:$C$110,A10,'Test Cases'!$G$5:$G$110,"?*") | H10: =COUNTIFS('Test Cases'!$C$5:$C$110,A10,'Test Cases'!$V$5:$V$110,"Automated") | I10: =COUNTIFS('Test Cases'!$C$5:$C$110,A10,'Test Cases'!$V$5:$V$110,"Blocked") | J10: =COUNTIFS('Test Cases'!$C$5:$C$110,A10,'Test Cases'!$T$5:$T$110,"Y")
A11: Document Upload | B11: =COUNTIF('Test Cases'!$C$5:$C$110,A11) | C11: =COUNTIFS('Test Cases'!$C$5:$C$110,A11,'Test Cases'!$P$5:$P$110,"P1") | D11: =COUNTIFS('Test Cases'!$C$5:$C$110,A11,'Test Cases'!$P$5:$P$110,"P2") | E11: =COUNTIFS('Test Cases'!$C$5:$C$110,A11,'Test Cases'!$P$5:$P$110,"P3") | F11: =COUNTIFS('Test Cases'!$C$5:$C$110,A11,'Test Cases'!$S$5:$S$110,"Y") | G11: =COUNTIFS('Test Cases'!$C$5:$C$110,A11,'Test Cases'!$G$5:$G$110,"?*") | H11: =COUNTIFS('Test Cases'!$C$5:$C$110,A11,'Test Cases'!$V$5:$V$110,"Automated") | I11: =COUNTIFS('Test Cases'!$C$5:$C$110,A11,'Test Cases'!$V$5:$V$110,"Blocked") | J11: =COUNTIFS('Test Cases'!$C$5:$C$110,A11,'Test Cases'!$T$5:$T$110,"Y")
A12: Validation Summary | B12: =COUNTIF('Test Cases'!$C$5:$C$110,A12) | C12: =COUNTIFS('Test Cases'!$C$5:$C$110,A12,'Test Cases'!$P$5:$P$110,"P1") | D12: =COUNTIFS('Test Cases'!$C$5:$C$110,A12,'Test Cases'!$P$5:$P$110,"P2") | E12: =COUNTIFS('Test Cases'!$C$5:$C$110,A12,'Test Cases'!$P$5:$P$110,"P3") | F12: =COUNTIFS('Test Cases'!$C$5:$C$110,A12,'Test Cases'!$S$5:$S$110,"Y") | G12: =COUNTIFS('Test Cases'!$C$5:$C$110,A12,'Test Cases'!$G$5:$G$110,"?*") | H12: =COUNTIFS('Test Cases'!$C$5:$C$110,A12,'Test Cases'!$V$5:$V$110,"Automated") | I12: =COUNTIFS('Test Cases'!$C$5:$C$110,A12,'Test Cases'!$V$5:$V$110,"Blocked") | J12: =COUNTIFS('Test Cases'!$C$5:$C$110,A12,'Test Cases'!$T$5:$T$110,"Y")
A13: Submission & Status Tracking | B13: =COUNTIF('Test Cases'!$C$5:$C$110,A13) | C13: =COUNTIFS('Test Cases'!$C$5:$C$110,A13,'Test Cases'!$P$5:$P$110,"P1") | D13: =COUNTIFS('Test Cases'!$C$5:$C$110,A13,'Test Cases'!$P$5:$P$110,"P2") | E13: =COUNTIFS('Test Cases'!$C$5:$C$110,A13,'Test Cases'!$P$5:$P$110,"P3") | F13: =COUNTIFS('Test Cases'!$C$5:$C$110,A13,'Test Cases'!$S$5:$S$110,"Y") | G13: =COUNTIFS('Test Cases'!$C$5:$C$110,A13,'Test Cases'!$G$5:$G$110,"?*") | H13: =COUNTIFS('Test Cases'!$C$5:$C$110,A13,'Test Cases'!$V$5:$V$110,"Automated") | I13: =COUNTIFS('Test Cases'!$C$5:$C$110,A13,'Test Cases'!$V$5:$V$110,"Blocked") | J13: =COUNTIFS('Test Cases'!$C$5:$C$110,A13,'Test Cases'!$T$5:$T$110,"Y")
A14: API Validation | B14: =COUNTIF('Test Cases'!$C$5:$C$110,A14) | C14: =COUNTIFS('Test Cases'!$C$5:$C$110,A14,'Test Cases'!$P$5:$P$110,"P1") | D14: =COUNTIFS('Test Cases'!$C$5:$C$110,A14,'Test Cases'!$P$5:$P$110,"P2") | E14: =COUNTIFS('Test Cases'!$C$5:$C$110,A14,'Test Cases'!$P$5:$P$110,"P3") | F14: =COUNTIFS('Test Cases'!$C$5:$C$110,A14,'Test Cases'!$S$5:$S$110,"Y") | G14: =COUNTIFS('Test Cases'!$C$5:$C$110,A14,'Test Cases'!$G$5:$G$110,"?*") | H14: =COUNTIFS('Test Cases'!$C$5:$C$110,A14,'Test Cases'!$V$5:$V$110,"Automated") | I14: =COUNTIFS('Test Cases'!$C$5:$C$110,A14,'Test Cases'!$V$5:$V$110,"Blocked") | J14: =COUNTIFS('Test Cases'!$C$5:$C$110,A14,'Test Cases'!$T$5:$T$110,"Y")
A15: Database Validation | B15: =COUNTIF('Test Cases'!$C$5:$C$110,A15) | C15: =COUNTIFS('Test Cases'!$C$5:$C$110,A15,'Test Cases'!$P$5:$P$110,"P1") | D15: =COUNTIFS('Test Cases'!$C$5:$C$110,A15,'Test Cases'!$P$5:$P$110,"P2") | E15: =COUNTIFS('Test Cases'!$C$5:$C$110,A15,'Test Cases'!$P$5:$P$110,"P3") | F15: =COUNTIFS('Test Cases'!$C$5:$C$110,A15,'Test Cases'!$S$5:$S$110,"Y") | G15: =COUNTIFS('Test Cases'!$C$5:$C$110,A15,'Test Cases'!$G$5:$G$110,"?*") | H15: =COUNTIFS('Test Cases'!$C$5:$C$110,A15,'Test Cases'!$V$5:$V$110,"Automated") | I15: =COUNTIFS('Test Cases'!$C$5:$C$110,A15,'Test Cases'!$V$5:$V$110,"Blocked") | J15: =COUNTIFS('Test Cases'!$C$5:$C$110,A15,'Test Cases'!$T$5:$T$110,"Y")
A16: Framework Self-Checks | B16: =COUNTIF('Test Cases'!$C$5:$C$110,A16) | C16: =COUNTIFS('Test Cases'!$C$5:$C$110,A16,'Test Cases'!$P$5:$P$110,"P1") | D16: =COUNTIFS('Test Cases'!$C$5:$C$110,A16,'Test Cases'!$P$5:$P$110,"P2") | E16: =COUNTIFS('Test Cases'!$C$5:$C$110,A16,'Test Cases'!$P$5:$P$110,"P3") | F16: =COUNTIFS('Test Cases'!$C$5:$C$110,A16,'Test Cases'!$S$5:$S$110,"Y") | G16: =COUNTIFS('Test Cases'!$C$5:$C$110,A16,'Test Cases'!$G$5:$G$110,"?*") | H16: =COUNTIFS('Test Cases'!$C$5:$C$110,A16,'Test Cases'!$V$5:$V$110,"Automated") | I16: =COUNTIFS('Test Cases'!$C$5:$C$110,A16,'Test Cases'!$V$5:$V$110,"Blocked") | J16: =COUNTIFS('Test Cases'!$C$5:$C$110,A16,'Test Cases'!$T$5:$T$110,"Y")
A17: Total | B17: =SUM(B5:B16) | C17: =SUM(C5:C16) | D17: =SUM(D5:D16) | E17: =SUM(E5:E16) | F17: =SUM(F5:F16) | G17: =SUM(G5:G16) | H17: =SUM(H5:H16) | I17: =SUM(I5:I16) | J17: =SUM(J5:J16)
A19: P1 share of all cases (Submission 1: 50%) | B19: =C17/B17
A20: Release gate within 15-20? | B20: =IF(AND(C17>=15,C17<=20),"Yes","No - review")
A21: Automation coverage (automated / total) | B21: =H17/B17
A22: Risks covered | B22: =COUNTIF('Traceability - Risks'!J5:J45,">0")&" of 41"
A23: Reported issues covered | B23: =COUNTIF('Traceability - Defects'!F5:F24,">0")&" of 20"
A25: Notes
A26: Automated = a Playwright test exists for the case. Blocked = cannot be automated yet (database access, Q04).
A27: Five live runs exist (Run Results sheet): v1 passed 5/15 smoke and 10/96 overall (RUN-2); the latest smoke run (RUN-5) passed 12/15 (2 API tests skipped as environment, 1 failure open: RIDER-V01, AD-13). The full suite has NOT been re-run since RUN-2.

Sheet Test Cases
A1: Test Case Design Sheet - Insurance Order Entry Platform (Submission 2)
A2: Generated from test-design/testCases.js. Edit the .js file (single source of truth) and re-run: npm run export:testdesign && python scripts/build_test_sheet.py
A4: Test Case ID | B4: Title | C4: Module | D4: Scenario ID | E4: Source | F4: Requirement / Risk Link (Submission 1 risk IDs) | G4: Seeded Defect Theme (reported issue) | H4: Seeded Defect Candidate / Catalog Code | I4: Test Type | J4: Layer | K4: Preconditions | L4: Test Steps | M4: Test Data | N4: Expected Result | O4: Severity | P4: Priority (P1 = release gate) | Q4: Submission 1 Priority | R4: Release Gate | S4: Smoke | T4: Sensitive Data (no trace/video) | U4: Evidence Required | V4: Automation Status | W4: Automated In | X4: Run Conditions / TBC | Y4: Open Questions | Z4: Blocked Reason | AA4: Tags | AB4: Live run 1 - smoke 26-Oct 11:38 (old code) | AC4: Live run 2 - full 26-Oct 11:51 (old code) | AD4: Live run 3 - smoke after fixes | AE4: Live run 4 - smoke 28-Oct | AF4: Live run 5 - smoke 28-Oct (later) | AG4: Defect Log IDs
A5: TC-AUTH-V01 | B5: Valid agent logs in and lands on their draft application (BR-AUTH-010) | C5: Authentication & Session | D5: AUTH-V01 | E5: S1 | F5: R01 | G5: RI-01: Valid agents cannot log in after authentication changes | H5: SDC-01 | I5: UI Positive | J5: UI | K5: Seeded valid agent exists and is active; browser has no session | L5: 1. Open /login 2. Enter valid agent email and password 3. Click Log in | M5: AGENT_VALID_EMAIL / AGENT_VALID_PASSWORD | N5: Browser leaves /login and lands on the draft application Client Information page (/applications/:id/client); the logout control is visible | O5: Critical | P5: P1 | Q5: P1 | R5: Y | S5: Y | T5: N | U5: Screenshot attached on pass AND fail; trace/video on failure; diagnostics.json (console + 5xx) | V5: Automated | W5: tests/ui/auth.spec.js | AA5: @regression @authentication @p1 @smoke @release-gate @seeded | AB5: Passed | AC5: Passed | AD5: Passed | AE5: Passed | AF5: Passed
A6: TC-AUTH-V02 | B6: Invalid password shows correct error message | C6: Authentication & Session | D6: AUTH-V02 | E6: S1 | F6: R02 | G6: RI-02: Locked or invalid agents get incorrect / misleading messages | H6: SDC-02 | I6: UI Negative | J6: UI | K6: Seeded valid agent exists; browser has no session | L6: 1. Open /login 2. Enter valid email with a WRONG password 3. Click Log in | M6: AGENT_VALID_EMAIL + AGENT_INVALID_PASSWORD | N6: Stays on /login; an invalid-credentials message is shown (config/messages.js invalidCredentials); dashboard is not reachable | O6: High | P6: P2 | Q6: P1 | R6: N | S6: N | T6: N | U6: Screenshot attached on pass AND fail; trace/video on failure; diagnostics.json (console + 5xx) | V6: Automated | W6: tests/ui/auth.spec.js | AA6: @regression @authentication @p2 @seeded | AB6: Not in smoke scope | AC6: Passed | AD6: Not in smoke scope | AE6: Not in smoke scope | AF6: Not in smoke scope | AG6: AD-07
A7: TC-AUTH-V03 | B7: Blank username/password show mandatory field errors | C7: Authentication & Session | D7: AUTH-V03 | E7: S1 | F7: R02 | I7: UI Negative | J7: UI | K7: Browser has no session | L7: 1. Open /login 2. Leave email and password empty 3. Click Log in | M7: none | N7: Stays on /login; each empty field is flagged as required (inline message or browser validity state) | O7: Medium | P7: P2 | Q7: P2 | R7: N | S7: N | T7: N | U7: Screenshot + trace on failure | V7: Automated | W7: tests/ui/auth.spec.js | AA7: @regression @authentication @p2 | AB7: Not in smoke scope | AC7: Passed | AD7: Not in smoke scope | AE7: Not in smoke scope | AF7: Not in smoke scope
A8: TC-AUTH-V04 | B8: Logout clears session; protected route redirects to login | C8: Authentication & Session | D8: AUTH-V04 | E8: S1 | F8: R05 | I8: UI Positive | J8: UI | K8: Valid agent (AGENT_VALID) signed in via saved session; environment reachable | L8: 1. Open the dashboard 2. Click Log out 3. Navigate directly to /dashboard | M8: Generated synthetic data (utils/dataBuilder.js) | N8: After logout the login page is shown; navigating to /dashboard redirects back to /login (no stale session) | O8: High | P8: P2 | Q8: P1 | R8: N | S8: Y | T8: N | U8: Screenshot + trace on failure | V8: Automated | W8: tests/ui/auth.spec.js | AA8: @regression @authentication @p2 @smoke | AB8: Passed | AC8: Not passed - investigate | AD8: Passed | AE8: Passed | AF8: Passed | AG8: AD-07
A9: TC-AUTH-V05 | B9: Direct /dashboard access without login is blocked | C9: Authentication & Session | D9: AUTH-V05 | E9: S1 | F9: R04 | I9: UI Security | J9: UI | K9: Fresh browser context with no cookies or storage | L9: 1. Navigate directly to /dashboard without logging in | M9: none | N9: Redirected to /login; no dashboard content is rendered | O9: Critical | P9: P1 | Q9: P1 | R9: Y | S9: Y | T9: N | U9: Screenshot + trace on failure | V9: Automated | W9: tests/ui/auth.spec.js | AA9: @regression @authentication @p1 @smoke @release-gate | AB9: Passed | AC9: Passed | AD9: Passed | AE9: Passed | AF9: Passed
A10: TC-AUTH-V06 | B10: Locked user cannot access dashboard; lock message shown | C10: Authentication & Session | D10: AUTH-V06 | E10: S1 | F10: R02 | G10: RI-02: Locked or invalid agents get incorrect / misleading messages | H10: SDC-02 | I10: UI Negative | J10: UI | K10: Seeded locked agent (AGENT_LOCKED) exists | L10: 1. Open /login 2. Enter locked agent credentials 3. Click Log in 4. Navigate to /dashboard | M10: AGENT_LOCKED_EMAIL / AGENT_LOCKED_PASSWORD | N10: Stays on /login with an account-locked message (not a generic "invalid password"); /dashboard redirects to login | O10: High | P10: P1 | Q10: P1 | R10: Y | S10: N | T10: N | U10: Screenshot attached on pass AND fail; trace/video on failure; diagnostics.json (console + 5xx) | V10: Automated | W10: tests/ui/auth.spec.js | AA10: @regression @authentication @p1 @release-gate @seeded | AB10: Not in smoke scope | AC10: Failed or skipped (not itemised) | AD10: Not in smoke scope | AE10: Not in smoke scope | AF10: Not in smoke scope
A11: TC-AUTH-V07 | B11: Account locks after five failed attempts | C11: Authentication & Session | D11: AUTH-V07 | E11: S1 | F11: R03 | G11: RI-02: Locked or invalid agents get incorrect / misleading messages | H11: SDC-02 | I11: UI Boundary | J11: UI + API | K11: DISPOSABLE agent (AGENT_LOCKOUT) that may be left locked; lock rule per assumption A06/Q07 | L11: 1. Attempt login with a wrong password 4 times 2. Confirm the message is still "invalid credentials" 3. Attempt a 5th wrong login (either message is acceptable - Q07) 4. Attempt login with the CORRECT password | M11: AGENT_LOCKOUT_EMAIL; LOCKOUT_ATTEMPTS (default 5) | N11: Attempts 1-4 show invalid-credentials; after the 5th failure the CORRECT password is refused with the account-locked message | O11: High | P11: P2 | Q11: P1 | R11: N | S11: N | T11: N | U11: Screenshot attached on pass AND fail; trace/video on failure; diagnostics.json (console + 5xx) | V11: Automated | W11: tests/ui/auth.spec.js | X11: Set AGENT_LOCKOUT_EMAIL (destructive: locks the account) | AA11: @regression @authentication @p2 @seeded @api | AB11: Not in smoke scope | AC11: Failed or skipped (not itemised) | AD11: Not in smoke scope | AE11: Not in smoke scope | AF11: Not in smoke scope
A12: TC-AUTH-V08 | B12: Password policy rejects weak password (reset/change) | C12: Authentication & Session | D12: AUTH-V08 | E12: S1 | F12: R06 | G12: RI-03: Password policy not consistently enforced | I12: UI Negative | J12: UI | K12: DISPOSABLE reset agent (AGENT_RESET); simulated OTP known (OTP_CODE) | L12: 1. Open /forgot-password and request a reset for the reset agent 2. Enter the OTP 3. For each weak password (short, no digit, no uppercase, common word) set it as the new password | M12: AGENT_RESET_EMAIL; OTP_CODE; weak password list in tests/ui/auth.spec.js | N12: Every weak password is rejected with a password-policy message; the password is not changed | O12: Medium | P12: P2 | Q12: P2 | R12: N | S12: N | T12: N | U12: Screenshot attached on pass AND fail; trace/video on failure; diagnostics.json (console + 5xx) | V12: Automated | W12: tests/ui/auth.spec.js | X12: Set AGENT_RESET_EMAIL and OTP_CODE (Q08, Q09) | Y12: Q08, Q09 | AA12: @regression @authentication @p2 @seeded | AB12: Not in smoke scope | AC12: Failed or skipped (not itemised) | AD12: Not in smoke scope | AE12: Not in smoke scope | AF12: Not in smoke scope
A13: TC-AUTH-V09 | B13: MFA/OTP simulation login | C13: Authentication & Session | D13: AUTH-V09 | E13: S1+ | F13: R01 | I13: UI Positive | J13: UI | K13: Seeded MFA agent (AGENT_MFA); simulated OTP known (OTP_CODE) | L13: 1. Log in with MFA agent credentials 2. Confirm OTP prompt 3. Enter a WRONG OTP 4. Enter the correct OTP | M13: AGENT_MFA_EMAIL; OTP_CODE | N13: OTP prompt appears; wrong OTP is rejected; correct OTP completes login to the dashboard | O13: High | P13: P2 | Q13: P2 | R13: N | S13: N | T13: N | U13: Screenshot + trace on failure | V13: Automated | W13: tests/ui/auth.spec.js | X13: Set OTP_CODE (Q08). agent.mfa is a confirmed seeded account | Y13: Q08 | AA13: @regression @authentication @p2 | AB13: Not in smoke scope | AC13: Failed or skipped (not itemised) | AD13: Not in smoke scope | AE13: Not in smoke scope | AF13: Not in smoke scope
A14: TC-AUTH-V14 | B14: Admin logs in and lands on the dashboard (carried over from the starter project as AUTH-V01b) | C14: Authentication & Session | D14: AUTH-V14 | E14: S2+ | F14: R01 | I14: UI Positive | J14: UI | K14: Seeded admin user exists and is active; browser has no session | L14: 1. Open /login 2. Enter admin email and password 3. Click Log in | M14: ADMIN_EMAIL + ADMIN_PASSWORD | N14: Browser lands on /dashboard (admin is the only role that does); the logout control is visible | O14: High | P14: P2 | Q14: P2 | R14: N | S14: Y | T14: N | U14: Screenshot attached on pass AND fail; trace/video on failure; diagnostics.json (console + 5xx) | V14: Automated | W14: tests/ui/auth.spec.js | AA14: @regression @authentication @p2 @smoke | AB14: Passed | AC14: Passed | AD14: Passed | AE14: Passed | AF14: Passed
A15: TC-AUTH-V10 | B15: Session timeout redirects to login | C15: Authentication & Session | D15: AUTH-V10 | E15: S1+ | F15: R05 | I15: UI Boundary | J15: UI | K15: Valid agent (AGENT_VALID) signed in via saved session; environment reachable | L15: 1. Log in 2. Stay idle for SESSION_TIMEOUT_SECONDS + 2 seconds 3. Navigate to a protected page | M15: SESSION_TIMEOUT_SECONDS (short value on a test environment) | N15: The expired session is redirected to /login | O15: High | P15: P2 | Q15: P2 | R15: N | S15: N | T15: N | U15: Screenshot + trace on failure | V15: Automated | W15: tests/ui/auth.spec.js | X15: Set SESSION_TIMEOUT_SECONDS (Q07); keep it small | Y15: Q07 | AA15: @regression @authentication @p2 | AB15: Not in smoke scope | AC15: Failed or skipped (not itemised) | AD15: Not in smoke scope | AE15: Not in smoke scope | AF15: Not in smoke scope
A16: TC-AUTH-V11 | B16: Forgot-password flow (/forgot-password) | C16: Authentication & Session | D16: AUTH-V11 | E16: S1+ | F16: R06 | I16: UI Positive | J16: UI | K16: Browser has no session | L16: 1. Open /login 2. Click the forgot-password link 3. Enter the agent email 4. Submit | M16: AGENT_VALID_EMAIL / AGENT_VALID_PASSWORD | N16: The forgot-password page opens and submitting a known email shows a confirmation or the OTP step (no error) | O16: Low | P16: P3 | Q16: P3 | R16: N | S16: N | T16: N | U16: Screenshot + trace on failure | V16: Automated | W16: tests/ui/auth.spec.js | AA16: @regression @authentication @p3 | AB16: Not in smoke scope | AC16: Passed | AD16: Not in smoke scope | AE16: Not in smoke scope | AF16: Not in smoke scope
A17: TC-AUTH-V12 | B17: Reset OTP: wrong OTP rejected; correct OTP reaches new-password step | C17: Authentication & Session | D17: AUTH-V12 | E17: S2+ | F17: R06 | I17: UI Negative | J17: UI | K17: DISPOSABLE reset agent (AGENT_RESET); simulated OTP known (OTP_CODE) | L17: 1. Open /forgot-password and request a reset 2. Enter a WRONG OTP 3. Enter the correct OTP | M17: AGENT_RESET_EMAIL; OTP_CODE | N17: Wrong OTP shows an OTP error and does not advance; correct OTP shows the new-password fields (password is NOT changed by this test) | O17: High | P17: P2 | Q17: P2 | R17: N | S17: N | T17: N | U17: Screenshot + trace on failure | V17: Automated | W17: tests/ui/auth.spec.js | X17: Set AGENT_RESET_EMAIL and OTP_CODE (Q08) | Y17: Q08 | AA17: @regression @authentication @p2 | AB17: Not in smoke scope | AC17: Failed or skipped (not itemised) | AD17: Not in smoke scope | AE17: Not in smoke scope | AF17: Not in smoke scope
A18: TC-AUTH-V13 | B18: New password identical to the current password is rejected | C18: Authentication & Session | D18: AUTH-V13 | E18: S2+ | F18: R06 | G18: RI-03: Password policy not consistently enforced | I18: UI Negative | J18: UI | K18: DISPOSABLE reset agent (AGENT_RESET); OTP_CODE known | L18: 1. Request reset and pass the OTP step 2. Enter the CURRENT password as the new password and confirm 3. Submit | M18: AGENT_RESET_EMAIL / AGENT_RESET_PASSWORD; OTP_CODE | N18: Rejected with a "must differ from current password" style message | O18: Medium | P18: P2 | Q18: P2 | R18: N | S18: N | T18: N | U18: Screenshot attached on pass AND fail; trace/video on failure; diagnostics.json (console + 5xx) | V18: Automated | W18: tests/ui/auth.spec.js | X18: Set AGENT_RESET_EMAIL and OTP_CODE | AA18: @regression @authentication @p2 @seeded | AB18: Not in smoke scope | AC18: Failed or skipped (not itemised) | AD18: Not in smoke scope | AE18: Not in smoke scope | AF18: Not in smoke scope
A19: TC-DASH-V01 | B19: Dashboard loads: draft/submitted summary and New Application CTA | C19: Agent Dashboard | D19: DASH-V01 | E19: S1 | F19: R07 | I19: UI Positive | J19: UI | K19: Valid agent (AGENT_VALID) signed in via saved session; environment reachable | L19: 1. Open the dashboard | M19: Generated synthetic data (utils/dataBuilder.js) | N19: New Application control is visible; draft and submitted summary figures are displayed as numbers | O19: High | P19: P2 | Q19: P1 | R19: N | S19: Y | T19: N | U19: Screenshot + trace on failure | V19: Automated | W19: tests/ui/dashboard.spec.js | AA19: @regression @dashboard @p2 @smoke | AB19: Passed | AC19: Not passed - investigate | AD19: Passed | AE19: Passed | AF19: Passed | AG19: AD-07
A20: TC-DASH-V02 | B20: Agent sees only own applications (multi-agent isolation) | C20: Agent Dashboard | D20: DASH-V02 | E20: S1 | F20: R08 | I20: UI Security | J20: UI + API | K20: Two seeded agents (AGENT_VALID, AGENT_SECOND), each with applications | L20: 1. Open dashboard as agent A and collect row identifiers 2. Open dashboard as agent B and collect row identifiers 3. Compare the two sets | M20: AGENT_VALID_*, AGENT_SECOND_* | N20: The two sets of application rows do not overlap | O20: Critical | P20: P1 | Q20: P1 | R20: Y | S20: N | T20: N | U20: Screenshot + trace on failure | V20: Automated | W20: tests/ui/dashboard.spec.js | X20: Second agent defaults to learner001 (confirmed seeded); override with AGENT_SECOND_EMAIL | AA20: @regression @dashboard @p1 @release-gate @api | AB20: Not in smoke scope | AC20: Failed or skipped (not itemised) | AD20: Not in smoke scope | AE20: Not in smoke scope | AF20: Not in smoke scope
A21: TC-DASH-V03 | B21: New agent sees empty-state copy and CTA | C21: Agent Dashboard | D21: DASH-V03 | E21: S1 | F21: R07 | I21: UI Positive | J21: UI | K21: Seeded NEW agent (AGENT_NEW) with zero applications | L21: 1. Sign in as the new agent 2. Open the dashboard | M21: AGENT_NEW_* | N21: Empty-state text and the New Application control are visible; no application rows | O21: Low | P21: P3 | Q21: P3 | R21: N | S21: N | T21: N | U21: Screenshot + trace on failure | V21: Automated | W21: tests/ui/dashboard.spec.js | X21: agent.new is a confirmed seeded account, but login auto-creates a draft (BR-AUTH-010) so the empty state may never appear - verify on the lab | AA21: @regression @dashboard @p3 | AB21: Not in smoke scope | AC21: Failed or skipped (not itemised) | AD21: Not in smoke scope | AE21: Not in smoke scope | AF21: Not in smoke scope | AG21: CL-02
A22: TC-DASH-V04 | B22: Draft can be resumed from dashboard with saved data | C22: Agent Dashboard | D22: DASH-V04 | E22: S1 | F22: R09 | G22: RI-16: Draft data not persisted | H22: SDC-16 | I22: UI Positive | J22: UI | K22: Valid agent (AGENT_VALID) signed in via saved session; environment reachable; client step reachable | L22: 1. Start a new application 2. Fill the client step and Save draft 3. Go to the dashboard 4. Resume the draft row 5. Read the client first name | M22: Generated synthetic data (utils/dataBuilder.js) | N22: The resumed draft shows the client first name that was saved | O22: High | P22: P2 | Q22: P2 | R22: N | S22: N | T22: N | U22: Screenshot attached on pass AND fail; trace/video on failure; diagnostics.json (console + 5xx) | V22: Automated | W22: tests/ui/dashboard.spec.js | AA22: @regression @dashboard @p2 @seeded | AB22: Not in smoke scope | AC22: Failed or skipped (not itemised) | AD22: Not in smoke scope | AE22: Not in smoke scope | AF22: Not in smoke scope
A23: TC-DASH-V05 | B23: Status filters (Draft/Submitted/Approved) return correct rows | C23: Agent Dashboard | D23: DASH-V05 | E23: S1 | F23: R07 | I23: UI Positive | J23: UI | K23: Valid agent (AGENT_VALID) signed in via saved session; environment reachable | L23: 1. Open the dashboard 2. For each status filter value (Draft, Submitted, Approved) apply the filter 3. Read the status of every visible row | M23: Generated synthetic data (utils/dataBuilder.js) | N23: Every visible row has the selected status (an empty result is acceptable only if no such applications exist) | O23: Medium | P23: P2 | Q23: P2 | R23: N | S23: N | T23: N | U23: Screenshot + trace on failure | V23: Automated | W23: tests/ui/dashboard.spec.js | AA23: @regression @dashboard @p2 | AB23: Not in smoke scope | AC23: Failed or skipped (not itemised) | AD23: Not in smoke scope | AE23: Not in smoke scope | AF23: Not in smoke scope | AG23: CL-01
A24: TC-DASH-V06 | B24: Dashboard status matches Application Status API | C24: Agent Dashboard | D24: DASH-V06 | E24: S1 | F24: R07 | G24: RI-18: Dashboard status differs from backend status | H24: SDC-18 | I24: UI-API Integration | J24: UI + API | K24: Valid agent (AGENT_VALID) signed in via saved session; environment reachable | L24: 1. Open the dashboard and read id and status of up to 5 rows 2. Call GET /applications/{id}/status for each 3. Compare | M24: Generated synthetic data (utils/dataBuilder.js) | N24: UI status equals API status for every compared application | O24: High | P24: P2 | Q24: P1 | R24: N | S24: N | T24: N | U24: Screenshot + API response attached | V24: Automated | W24: tests/integration/ui-api.spec.js | AA24: @regression @dashboard @p2 @seeded @api | AB24: Not in smoke scope | AC24: Failed or skipped (not itemised) | AD24: Not in smoke scope | AE24: Not in smoke scope | AF24: Not in smoke scope
A25: TC-DASH-V07 | B25: Dashboard search returns matching applications | C25: Agent Dashboard | D25: DASH-V07 | E25: S1+ | F25: R07 | I25: UI Positive | J25: UI | K25: Valid agent (AGENT_VALID) signed in via saved session; environment reachable; at least one application exists | L25: 1. Open the dashboard 2. Take a search term from the first row 3. Search for it | M25: Generated synthetic data (utils/dataBuilder.js) | N25: At least one row is shown and every shown row contains the term | O25: Low | P25: P3 | Q25: P3 | R25: N | S25: N | T25: N | U25: Screenshot + trace on failure | V25: Automated | W25: tests/ui/dashboard.spec.js | AA25: @regression @dashboard @p3 | AB25: Not in smoke scope | AC25: Failed or skipped (not itemised) | AD25: Not in smoke scope | AE25: Not in smoke scope | AF25: Not in smoke scope | AG25: CL-01
A26: TC-CLI-V01 | B26: Valid insured personal information enables next step | C26: Client / Insured Information | D26: CLI-V01 | E26: S1 | F26: R10 | I26: UI Positive | J26: UI | K26: Valid agent (AGENT_VALID) signed in via saved session; environment reachable; NEW application open at the client step (first step) | L26: 1. Fill every client field with valid data 2. Click Next | M26: Generated synthetic data (utils/dataBuilder.js) | N26: Navigation moves to the next step (step title changes) with no validation errors | O26: Critical | P26: P2 | Q26: P1 | R26: N | S26: Y | T26: N | U26: Screenshot + trace on failure | V26: Automated | W26: tests/ui/client.spec.js | AA26: @regression @client @p2 @smoke | AB26: Failed | AC26: Failed | AD26: Passed | AE26: Passed | AF26: Passed | AG26: AD-01, AD-02, AD-05, AD-06
A27: TC-CLI-V02 | B27: Mandatory personal fields validated inline | C27: Client / Insured Information | D27: CLI-V02 | E27: S1 | F27: R10 | I27: UI Negative | J27: UI | K27: Valid agent (AGENT_VALID) signed in via saved session; environment reachable; NEW application open at the client step (first step) | L27: 1. Leave all client fields empty 2. Click Next | M27: none | N27: User stays on the step; first name, last name and date of birth each show a required message | O27: Medium | P27: P2 | Q27: P2 | R27: N | S27: N | T27: N | U27: Screenshot + trace on failure | V27: Automated | W27: tests/ui/client.spec.js | AA27: @regression @client @p2 | AB27: Not in smoke scope | AC27: Failed or skipped (not itemised) | AD27: Not in smoke scope | AE27: Not in smoke scope | AF27: Not in smoke scope
A28: TC-CLI-V03 | B28: DOB under 18 rejected (age boundary) | C28: Client / Insured Information | D28: CLI-V03 | E28: S1 | F28: R10 | G28: RI-04: Client age eligibility rules (18-65) missed | H28: SDC-04 | I28: UI Boundary | J28: UI + API | K28: Valid agent (AGENT_VALID) signed in via saved session; environment reachable; NEW application open at the client step (first step) | L28: 1. Enter DOB for a person who turns 18 TOMORROW (age 17) and click Next 2. Enter DOB for a person exactly 18 today and click Next | M28: dobForAge(18,{dayOffset:1}) and dobForAge(18) | N28: Age 17 is rejected with an eligibility message and the step does not advance; age 18 is accepted (inclusive rule - assumption A06 / Q10) | O28: High | P28: P2 | Q28: P1 | R28: N | S28: N | T28: N | U28: Screenshot attached on pass AND fail; trace/video on failure; diagnostics.json (console + 5xx) | V28: Automated | W28: tests/ui/client.spec.js | AA28: @regression @client @p2 @seeded @api | AB28: Not in smoke scope | AC28: Failed or skipped (not itemised) | AD28: Not in smoke scope | AE28: Not in smoke scope | AF28: Not in smoke scope
A29: TC-CLI-V04 | B29: DOB over 65 rejected (age boundary) | C29: Client / Insured Information | D29: CLI-V04 | E29: S1 | F29: R10 | G29: RI-04: Client age eligibility rules (18-65) missed | H29: SDC-04 | I29: UI Boundary | J29: UI + API | K29: Valid agent (AGENT_VALID) signed in via saved session; environment reachable; NEW application open at the client step (first step) | L29: 1. Enter DOB for a person exactly 66 years old and click Next 2. Enter DOB for a person exactly 65 today and click Next | M29: dobForAge(66) and dobForAge(65) | N29: Age 66 is rejected with an eligibility message; age 65 is accepted (inclusive rule - A06 / Q10) | O29: High | P29: P2 | Q29: P1 | R29: N | S29: N | T29: N | U29: Screenshot attached on pass AND fail; trace/video on failure; diagnostics.json (console + 5xx) | V29: Automated | W29: tests/ui/client.spec.js | AA29: @regression @client @p2 @seeded @api | AB29: Not in smoke scope | AC29: Failed or skipped (not itemised) | AD29: Not in smoke scope | AE29: Not in smoke scope | AF29: Not in smoke scope
A30: TC-CLI-V05 | B30: Future DOB rejected | C30: Client / Insured Information | D30: CLI-V05 | E30: S1 | F30: R11 | G30: RI-05: Future date of birth accepted | H30: SDC-05 | I30: UI Negative | J30: UI + API | K30: Valid agent (AGENT_VALID) signed in via saved session; environment reachable; NEW application open at the client step (first step) | L30: 1. Enter a DOB of tomorrow and click Next 2. Enter a DOB 5 years in the future and click Next | M30: futureDate(1), futureDate(1825) | N30: Both dates are rejected with an invalid-date message and the step does not advance | O30: High | P30: P1 | Q30: P1 | R30: Y | S30: N | T30: N | U30: Screenshot attached on pass AND fail; trace/video on failure; diagnostics.json (console + 5xx) | V30: Automated | W30: tests/ui/client.spec.js | AA30: @regression @client @p1 @release-gate @seeded @api | AB30: Not in smoke scope | AC30: Failed or skipped (not itemised) | AD30: Not in smoke scope | AE30: Not in smoke scope | AF30: Not in smoke scope
A31: TC-CLI-V06 | B31: Same-as-residential copies address to mailing address | C31: Client / Insured Information | D31: CLI-V06 | E31: S1 | F31: R15 | I31: UI Positive | J31: UI | K31: Valid agent (AGENT_VALID) signed in via saved session; environment reachable; NEW application open at the address step with every earlier step completed using valid data | L31: 1. Fill the residential address 2. Tick "same as residential" 3. Read the mailing address fields | M31: Generated synthetic data (utils/dataBuilder.js) | N31: Mailing line 1, city and ZIP equal the residential values | O31: Low | P31: P3 | Q31: P3 | R31: N | S31: N | T31: N | U31: Screenshot + trace on failure | V31: Automated | W31: tests/ui/client.spec.js | AA31: @regression @client @p3 | AB31: Not in smoke scope | AC31: Failed or skipped (not itemised) | AD31: Not in smoke scope | AE31: Not in smoke scope | AF31: Not in smoke scope
A32: TC-CLI-V07 | B32: Invalid email and phone formats rejected | C32: Client / Insured Information | D32: CLI-V07 | E32: S1 | F32: R15 | I32: UI Negative | J32: UI | K32: Valid agent (AGENT_VALID) signed in via saved session; environment reachable; NEW application open at the address step with every earlier step completed using valid data | L32: 1. Fill a valid address 2. For each invalid email (no @, no domain, spaces) enter it and click Next 3. For each invalid phone (letters, too short) enter it and click Next | M32: Invalid email / phone lists in tests/ui/client.spec.js | N32: Each invalid value shows a format error next to the field and the step does not advance | O32: Medium | P32: P2 | Q32: P2 | R32: N | S32: N | T32: N | U32: Screenshot + trace on failure | V32: Automated | W32: tests/ui/client.spec.js | AA32: @regression @client @p2 | AB32: Not in smoke scope | AC32: Failed or skipped (not itemised) | AD32: Not in smoke scope | AE32: Not in smoke scope | AF32: Not in smoke scope
A33: TC-CLI-V08 | B33: SSN masked after entry (only last four digits visible) | C33: Client / Insured Information | D33: CLI-V08 | E33: S1 | F33: R12 | G33: RI-07: SSN not masked properly | H33: SDC-07 | I33: UI Security | J33: UI | K33: Valid agent (AGENT_VALID) signed in via saved session; environment reachable; NEW application open at the kyc step with every earlier step completed using valid data | L33: 1. Enter the synthetic SSN 900-12-3456 2. Leave the field (blur) 3. Read what is visible for the SSN | M33: Synthetic SSN 900-12-3456 (900-series is never issued) | N33: Only the last four digits (3456) are visible; the first five digits are masked | O33: Critical | P33: P1 | Q33: P1 | R33: Y | S33: N | T33: Y | U33: Screenshot attached on pass AND fail; trace/video on failure; diagnostics.json (console + 5xx) | V33: Automated | W33: tests/ui/client-kyc-sensitive.spec.js | AA33: @regression @client @p1 @release-gate @sensitive @seeded | AB33: Not in smoke scope | AC33: Failed or skipped (not itemised) | AD33: Not in smoke scope | AE33: Not in smoke scope | AF33: Not in smoke scope | AG33: AD-08
A34: TC-CLI-V09 | B34: KYC upload rejects unsupported file type | C34: Client / Insured Information | D34: CLI-V09 | E34: S1 | F34: R30 | I34: UI Negative | J34: UI | K34: Valid agent (AGENT_VALID) signed in via saved session; environment reachable; NEW application open at the kyc step with every earlier step completed using valid data | L34: 1. Upload an .exe file in the KYC document control | M34: In-memory malware-test.exe | N34: An unsupported-type message is shown and the file is not accepted | O34: Medium | P34: P2 | Q34: P2 | R34: N | S34: N | T34: Y | U34: Screenshot + trace on failure | V34: Automated | W34: tests/ui/client-kyc-sensitive.spec.js | X34: Skips if the KYC step has no upload control | AA34: @regression @client @p2 @sensitive | AB34: Not in smoke scope | AC34: Failed or skipped (not itemised) | AD34: Not in smoke scope | AE34: Not in smoke scope | AF34: Not in smoke scope
A35: TC-CLI-V10 | B35: PEP = Yes makes additional details mandatory | C35: Client / Insured Information | D35: CLI-V10 | E35: S1 | F35: R14 | I35: UI Negative | J35: UI | K35: Valid agent (AGENT_VALID) signed in via saved session; environment reachable; NEW application open at the kyc step with every earlier step completed using valid data | L35: 1. Select PEP = Yes 2. Confirm the PEP details field appears 3. Click Next without details | M35: Generated synthetic data (utils/dataBuilder.js) | N35: PEP details field becomes visible and Next is blocked with a required message until it is filled | O35: Medium | P35: P2 | Q35: P2 | R35: N | S35: N | T35: Y | U35: Screenshot + trace on failure | V35: Automated | W35: tests/ui/client-kyc-sensitive.spec.js | AA35: @regression @client @p2 @sensitive | AB35: Not in smoke scope | AC35: Failed or skipped (not itemised) | AD35: Not in smoke scope | AE35: Not in smoke scope | AF35: Not in smoke scope
A36: TC-CLI-V11 | B36: Postal code format validated | C36: Client / Insured Information | D36: CLI-V11 | E36: S1+ | F36: R15 | I36: UI Negative | J36: UI | K36: Valid agent (AGENT_VALID) signed in via saved session; environment reachable; NEW application open at the address step with every earlier step completed using valid data | L36: 1. Fill a valid address with an invalid ZIP (letters, too short, too long) 2. Click Next | M36: ZIPs: ABCDE, 123, 0211000000 | N36: Each invalid ZIP is rejected with a postal-code message | O36: Low | P36: P3 | Q36: P3 | R36: N | S36: N | T36: N | U36: Screenshot + trace on failure | V36: Automated | W36: tests/ui/client.spec.js | AA36: @regression @client @p3 | AB36: Not in smoke scope | AC36: Failed or skipped (not itemised) | AD36: Not in smoke scope | AE36: Not in smoke scope | AF36: Not in smoke scope
A37: TC-CLI-V12 | B37: Income vs premium affordability validation | C37: Client / Insured Information | D37: CLI-V12 | E37: S1+ | F37: R13 | G37: RI-08: Income vs premium affordability not applied | H37: SDC-08 | I37: UI Negative | J37: UI + API | K37: Valid agent (AGENT_VALID) signed in via saved session; environment reachable; NEW application open at the kyc step with every earlier step completed using valid data | L37: 1. Enter a very LOW annual income 2. Continue to Product and select a product with a very HIGH face value 3. Click Next | M37: income 12000; face value 5,000,000 (rule undefined - Q11) | N37: An affordability warning or block referring to income/premium is shown (formula TBC with the product owner) | O37: High | P37: P2 | Q37: P1 | R37: N | S37: N | T37: Y | U37: Screenshot attached on pass AND fail; trace/video on failure; diagnostics.json (console + 5xx) | V37: Automated | W37: tests/ui/client-kyc-sensitive.spec.js | AA37: @regression @client @p2 @sensitive @seeded @api | AB37: Not in smoke scope | AC37: Failed or skipped (not itemised) | AD37: Not in smoke scope | AE37: Not in smoke scope | AF37: Not in smoke scope
A38: TC-CLI-V13 | B38: Calculated age shown on review matches the date of birth | C38: Client / Insured Information | D38: CLI-V13 | E38: S2+ | F38: R10 | G38: RI-04: Client age eligibility rules (18-65) missed | H38: SDC-04 | I38: UI Positive | J38: UI | K38: Valid agent (AGENT_VALID) signed in via saved session; environment reachable | L38: 1. Complete a journey with a DOB exactly 35 years before today 2. Read "Calculated Age" on the review page | M38: dobForAge(35) | N38: The age shown is 35 (the live app shows the calculated age only on the review snapshot) | O38: Medium | P38: P2 | Q38: P2 | R38: N | S38: N | T38: N | U38: DOB entered and age shown attached to the report | V38: Automated | W38: tests/ui/client.spec.js | AA38: @regression @client @p2 @seeded | AB38: Not in smoke scope | AC38: Failed or skipped (not itemised) | AD38: Not in smoke scope | AE38: Not in smoke scope | AF38: Not in smoke scope | AG38: AC-04
A39: TC-CLI-V14 | B39: Name validation rejects digits and special characters | C39: Client / Insured Information | D39: CLI-V14 | E39: S2+ | F39: R15 | I39: UI Negative | J39: UI | K39: Valid agent (AGENT_VALID) signed in via saved session; environment reachable; NEW application open at the client step (first step) | L39: 1. Enter a first name containing digits, click Next 2. Enter a last name containing special characters, click Next | M39: First name "J0hn123"; last name "O@#$%" | N39: Each invalid name is rejected with a name-format message and the step does not advance | O39: Medium | P39: P2 | Q39: P2 | R39: N | S39: N | T39: N | U39: Screenshot + trace on failure | V39: Automated | W39: tests/ui/client.spec.js | AA39: @regression @client @p2 | AB39: Not in smoke scope | AC39: Failed or skipped (not itemised) | AD39: Not in smoke scope | AE39: Not in smoke scope | AF39: Not in smoke scope
A40: TC-CLI-V15 | B40: State is required and validated | C40: Client / Insured Information | D40: CLI-V15 | E40: S2+ | F40: R15 | I40: UI Negative | J40: UI | K40: Valid agent (AGENT_VALID) signed in via saved session; environment reachable; NEW application open at the address step with every earlier step completed using valid data | L40: 1. Fill a valid address but clear the state selection 2. Click Next | M40: Generated synthetic data (utils/dataBuilder.js) | N40: A state-required message is shown and the step does not advance | O40: Medium | P40: P2 | Q40: P2 | R40: N | S40: N | T40: N | U40: Screenshot + trace on failure | V40: Automated | W40: tests/ui/client.spec.js | X40: Skips if the state control has no empty option | AA40: @regression @client @p2 | AB40: Not in smoke scope | AC40: Failed or skipped (not itemised) | AD40: Not in smoke scope | AE40: Not in smoke scope | AF40: Not in smoke scope
A41: TC-PROD-V01 | B41: Catalog displays expected Whole Life products | C41: Product Selection & Policy Configuration | D41: PROD-V01 | E41: S1 | F41: R16 | I41: UI Positive | J41: UI | K41: Valid agent (AGENT_VALID) signed in via saved session; environment reachable; NEW application open at the product step with every earlier step completed using valid data | L41: 1. Open the product step 2. Read the product cards | M41: PRODUCT_NAME_PATTERN (default "whole life") | N41: At least one product card is shown and at least one matches the Whole Life pattern | O41: High | P41: P1 | Q41: P1 | R41: Y | S41: Y | T41: N | U41: Screenshot + trace on failure | V41: Automated | W41: tests/ui/product.spec.js | AA41: @regression @product @p1 @smoke @release-gate | AB41: Failed | AC41: Failed | AD41: Passed | AE41: Passed | AF41: Passed | AG41: AD-01, AD-02, AD-04
...

Sheet Release Gate
A1: Release Gate (P1) - the scenarios that MUST pass for a release
A2: Submission 1 rated 52 of 105 scenarios P1. P1 is now limited to these. Everything else is regression (P2) or P3. Run: npm run test:gate
A4: Test Case ID | B4: Title | C4: Why a failure blocks the release | D4: Layer | E4: Automation Status | F4: Linked Risks
A5: TC-AUTH-V01 | B5: Valid agent logs in and lands on their draft application (BR-AUTH-010) | C5: If valid agents cannot sign in, nothing else is usable. | D5: UI | E5: Automated | F5: R01
A6: TC-AUTH-V05 | B6: Direct /dashboard access without login is blocked | C6: Protected pages must not be reachable without a session. | D6: UI | E6: Automated | F6: R04
A7: TC-AUTH-V06 | B7: Locked user cannot access dashboard; lock message shown | C7: Locked agents must stay locked out, with the correct message. | D7: UI | E7: Automated | F7: R02
A8: TC-DASH-V02 | B8: Agent sees only own applications (multi-agent isolation) | C8: An agent must never see another agent's applications (confidentiality). | D8: UI + API | E8: Automated | F8: R08
A9: TC-CLI-V05 | B9: Future DOB rejected | C9: A future date of birth would create an invalid policy. | D9: UI + API | E9: Automated | F9: R11
A10: TC-CLI-V08 | B10: SSN masked after entry (only last four digits visible) | C10: Unmasked SSN is a compliance / privacy breach. | D10: UI | E10: Automated | F10: R12
A11: TC-PROD-V01 | B11: Catalog displays expected Whole Life products | C11: Agents cannot sell if the product catalogue does not load. | D11: UI | E11: Automated | F11: R16
A12: TC-PROD-V05 | B12: Premium recalculates when frequency changes | C12: Wrong premium after a configuration change misprices the policy. | D12: UI + API | E12: Automated | F12: R18
A13: TC-PROD-V06 | B13: Review-page premium matches configuration page | C13: Premium on review must equal what the agent configured. | D13: UI + DB | E13: Automated | F13: R18, R19
A14: TC-RIDER-V02 | B14: Rider coverage cannot exceed base face value | C14: Rider cover above the base face value is an invalid coverage. | D14: UI + API | E14: Automated | F14: R20
A15: TC-BEN-V02 | B15: Primary allocation below 100% blocks progression | C15: Allocations must total 100% or payouts are disputed. | D15: UI + API + DB | E15: Automated | F15: R24
... A23: TC-API-V05 | B23: Submit API rejects incomplete application | C23: The submit API must refuse incomplete applications. | D23: API + DB | E23: Automated | F23: R29, R35
A25: Gate size | B25: =COUNTIF('Test Cases'!$P$5:$P$110,"P1")
A26: Target | B26: 15 to 20 scenarios
A27: Within target? | B27: =IF(AND(B25>=15,B25<=20),"Yes","No - review")

Sheet Traceability - Risks
A1: Traceability: Submission 1 risk register (R01-R41) to test cases
A2: Linked test cases are counted by formula from the Test Cases sheet.
A4: Risk ID | B4: Module | C4: Layer | D4: Risk | E4: Likelihood | F4: Impact | G4: Rating | H4: Covered by (Submission 1) | I4: Linked Test Cases | J4: # Test Cases
A5: R01 | B5: Authentication | C5: UI | D5: Valid agents cannot log in after authentication changes | E5: Medium | F5: High | G5: High | H5: AUTH-V01 | I5: TC-AUTH-V01, TC-AUTH-V09, TC-AUTH-V14 | J5: =COUNTIF('Test Cases'!$F$5:$F$110,"*"&A5&"*")
A6: R02 | B6: Authentication | C6: UI | D6: Locked or invalid users see incorrect or misleading messages | E6: Medium | F6: Medium | G6: Medium | H6: AUTH-V02, V06 | I6: TC-AUTH-V02, TC-AUTH-V03, TC-AUTH-V06 | J6: =COUNTIF('Test Cases'!$F$5:$F$110,"*"&A6&"*")
A7: R03 | B7: Authentication | C7: API/DB | D7: Lockout after five failures not enforced server-side or counter not stored | E7: Medium | F7: High | G7: High | H7: AUTH-V07, DB-10 | I7: TC-AUTH-V07, TC-DB-10 | J7: =COUNTIF('Test Cases'!$F$5:$F$110,"*"&A7&"*")
A8: R04 | B8: Authentication | C8: API | D8: Protected pages or endpoints reachable without authentication | E8: Low | F8: High | G8: Medium | H8: AUTH-V05, API-V02 | I8: TC-AUTH-V05, TC-API-V02 | J8: =COUNTIF('Test Cases'!$F$5:$F$110,"*"&A8&"*")
A9: R05 | B9: Authentication | C9: UI/API | D9: Session not cleared on logout; no session timeout | E9: Medium | F9: High | G9: High | H9: AUTH-V04, AUTH-V10 | I9: TC-AUTH-V04, TC-AUTH-V10 | J9: =COUNTIF('Test Cases'!$F$5:$F$110,"*"&A9&"*")
A10: R06 | B10: Authentication | C10: UI | D10: Password policy inconsistently enforced | E10: Medium | F10: Medium | G10: Medium | H10: AUTH-V08 | I10: TC-AUTH-V08, TC-AUTH-V11, TC-AUTH-V12, TC-AUTH-V13 | J10: =COUNTIF('Test Cases'!$F$5:$F$110,"*"&A10&"*")
A11: R07 | B11: Dashboard | C11: UI/API/DB | D11: Dashboard status differs from backend status | E11: Medium | F11: High | G11: High | H11: DASH-V06, API-V06, DB-03 | I11: TC-DASH-V01, TC-DASH-V03, TC-DASH-V05, TC-DASH-V06, TC-DASH-V07, TC-WF-V06, TC-WF-V07, TC-API-V06, TC-DB-03 | J11: =COUNTIF('Test Cases'!$F$5:$F$110,"*"&A11&"*")
A12: R08 | B12: Dashboard | C12: API/DB | D12: Agent sees another agent's applications | E12: Low | F12: High | G12: Medium | H12: DASH-V02, API-V08, DB-09 | I12: TC-DASH-V02, TC-API-V08, TC-DB-09 | J12: =COUNTIF('Test Cases'!$F$5:$F$110,"*"&A12&"*")
A13: R09 | B13: Dashboard | C13: UI | D13: Resumed draft shows missing or stale data | E13: Medium | F13: Medium | G13: Medium | H13: DASH-V04, WF-V02 | I13: TC-DASH-V04, TC-WF-V02 | J13: =COUNTIF('Test Cases'!$F$5:$F$110,"*"&A13&"*")
A14: R10 | B14: Client / KYC | C14: UI/API | D14: Age eligibility (18-65) rules missed | E14: Medium | F14: High | G14: High | H14: CLI-V03, V04 | I14: TC-CLI-V01, TC-CLI-V02, TC-CLI-V03, TC-CLI-V04, TC-CLI-V13 | J14: =COUNTIF('Test Cases'!$F$5:$F$110,"*"&A14&"*")
A15: R11 | B15: Client / KYC | C15: UI/API | D15: Future date of birth accepted | E15: Medium | F15: High | G15: High | H15: CLI-V05, API-V03 | I15: TC-CLI-V05, TC-API-V03 | J15: =COUNTIF('Test Cases'!$F$5:$F$110,"*"&A15&"*")
A16: R12 | B16: Client / KYC | C16: UI/DB | D16: SSN displayed unmasked, or stored/logged in clear text | E16: Medium | F16: High | G16: High | H16: CLI-V08, DB-07 | I16: TC-CLI-V08, TC-DB-07 | J16: =COUNTIF('Test Cases'!$F$5:$F$110,"*"&A16&"*")
... A45: R41 | B45: Cross-cutting | C45: DB | D45: Database access or schema not available for backend validation | E45: Medium | F45: Medium | G45: Medium | H45: DB-01..DB-10 | I45: TC-DB-01, TC-DB-02, TC-DB-03, TC-DB-04, TC-DB-05, TC-DB-06, TC-DB-07, TC-DB-08, TC-DB-09, TC-DB-10 | J45: =COUNTIF('Test Cases'!$F$5:$F$110,"*"&A45&"*")
A47: Risks with no test case | D47: =COUNTIF(J5:J45,0)

Sheet Traceability - Defects
A1: Traceability: seeded-defect themes (20 reported issues) to test cases
A2: SDC = "seeded-defect-candidate" id used by the third project's tests. The official DEF-* catalogue codes have still not been received. Column D holds the SDC id where a tagged test matches the theme; RI-03, RI-09, RI-11 and RI-20 have none yet. Detection status is only set from evidence: the live runs never reached the validation rules, so almost everything is Not run.
A4: Reported Issue ID | B4: Module | C4: Description | D4: Seeded Defect Catalog Code (fill) | E4: Linked Test Cases | F4: # Test Cases | G4: Detected in run? (fill: Detected / Not detected / Not run) | H4: Defect Log ID (fill)
A5: RI-01 | B5: Authentication | C5: Valid agents cannot log in after authentication changes | D5: SDC-01 | E5: TC-AUTH-V01 | F5: =COUNTIF('Test Cases'!$G$5:$G$110,"*"&A5&"*") | G5: Not detected
A6: RI-02 | B6: Authentication | C6: Locked or invalid agents get incorrect / misleading messages | D6: SDC-02 | E6: TC-AUTH-V02, TC-AUTH-V06, TC-AUTH-V07 | F6: =COUNTIF('Test Cases'!$G$5:$G$110,"*"&A6&"*") | G6: Not run | H6: AD-07
A7: RI-03 | B7: Authentication | C7: Password policy not consistently enforced | E7: TC-AUTH-V08, TC-AUTH-V13 | F7: =COUNTIF('Test Cases'!$G$5:$G$110,"*"&A7&"*") | G7: Not run
A8: RI-04 | B8: Client / KYC | C8: Client age eligibility rules (18-65) missed | D8: SDC-04 | E8: TC-CLI-V03, TC-CLI-V04, TC-CLI-V13 | F8: =COUNTIF('Test Cases'!$G$5:$G$110,"*"&A8&"*") | G8: Not run | H8: AC-04
A9: RI-05 | B9: Client / KYC | C9: Future date of birth accepted | D9: SDC-05 | E9: TC-CLI-V05, TC-API-V03, TC-API-V12 | F9: =COUNTIF('Test Cases'!$G$5:$G$110,"*"&A9&"*") | G9: Not run
A10: RI-06 | B10: Documents / Validation | C10: Mandatory KYC documents not enforced | D10: SDC-06 | E10: TC-DOC-V04, TC-API-V05 | F10: =COUNTIF('Test Cases'!$G$5:$G$110,"*"&A10&"*") | G10: Not run
A11: RI-07 | B11: Client / KYC | C11: SSN not masked properly | D11: SDC-07 | E11: TC-CLI-V08 | F11: =COUNTIF('Test Cases'!$G$5:$G$110,"*"&A11&"*") | G11: Not run | H11: AD-08
A12: RI-08 | B12: Client / KYC | C12: Income vs premium affordability not applied | D12: SDC-08 | E12: TC-CLI-V12 | F12: =COUNTIF('Test Cases'!$G$5:$G$110,"*"&A12&"*") | G12: Not run
A13: RI-09 | B13: Product / Policy | C13: Product eligibility not validated against age / suitability | E13: TC-PROD-V07, TC-PROD-V08 | F13: =COUNTIF('Test Cases'!$G$5:$G$110,"*"&A13&"*") | G13: Not run
A14: RI-10 | B14: Riders | C14: Rider coverage exceeds base face value | D14: SDC-10 | E14: TC-RIDER-V02 | F14: =COUNTIF('Test Cases'!$G$5:$G$110,"*"&A14&"*") | G14: Not run
A15: RI-11 | B15: Riders | C15: Exclusive waiver riders both selectable | E15: TC-RIDER-V05 | F15: =COUNTIF('Test Cases'!$G$5:$G$110,"*"&A15&"*") | G15: Not run
A16: RI-12 | B16: Product / Policy | C16: Premium not updated after configuration change | D16: SDC-12 | E16: TC-PROD-V05, TC-PROD-V06, TC-RIDER-V07 | F16: =COUNTIF('Test Cases'!$G$5:$G$110,"*"&A16&"*") | G16: Not run | H16: AD-13
A17: RI-13 | B17: Beneficiaries | C17: Allocation below / above 100% allowed | D17: SDC-13 | E17: TC-BEN-V02, TC-BEN-V03, TC-API-V04 | F17: =COUNTIF('Test Cases'!$G$5:$G$110,"*"&A17&"*") | G17: Not run
A18: RI-14 | B18: Beneficiaries | C18: Minor beneficiary guardian not required | D18: SDC-14 | E18: TC-BEN-V05 | F18: =COUNTIF('Test Cases'!$G$5:$G$110,"*"&A18&"*") | G18: Not run
A19: RI-15 | B19: Beneficiaries | C19: Duplicate beneficiaries not blocked | D19: SDC-15 | E19: TC-BEN-V08 | F19: =COUNTIF('Test Cases'!$G$5:$G$110,"*"&A19&"*") | G19: Not run
A20: RI-16 | B20: Submission / Status | C20: Draft data not persisted | D20: SDC-16 | E20: TC-DASH-V04, TC-PROD-V11, TC-WF-V01, TC-WF-V02 | F20: =COUNTIF('Test Cases'!$G$5:$G$110,"*"&A20&"*") | G20: Not run
A21: RI-17 | B21: Documents / Validation | C21: Submit enabled despite validation errors | D21: SDC-17 | E21: TC-VAL-V03 | F21: =COUNTIF('Test Cases'!$G$5:$G$110,"*"&A21&"*") | G21: Not run | H21: AC-01
A22: RI-18 | B22: Dashboard | C22: Dashboard status differs from backend status | D22: SDC-18 | E22: TC-DASH-V06, TC-WF-V06, TC-WF-V07, TC-API-V06 | F22: =COUNTIF('Test Cases'!$G$5:$G$110,"*"&A22&"*") | G22: Not run
A23: RI-19 | B23: Cross-cutting | C23: API validation differs from UI validation | D23: SDC-19 | E23: TC-API-V03, TC-API-V04, TC-API-V07, TC-API-V12 | F23: =COUNTIF('Test Cases'!$G$5:$G$110,"*"&A23&"*") | G23: Not run | H23: AD-03, AC-02
A24: RI-20 | B24: Cross-cutting | C24: Failures hard to debug (no consistent evidence) | E24: TC-FW-01 | F24: =COUNTIF('Test Cases'!$G$5:$G$110,"*"&A24&"*") | G24: Not run
A26: Detection rate | C26: =IF(COUNTIF(G5:G24,"Detected")+COUNTIF(G5:G24,"Not detected")=0,"n/a",COUNTIF(G5:G24,"Detected")/(COUNTIF(G5:G24,"Detected")+COUNTIF(G5:G24,"Not detected")))

Sheet Run Results
A1: Live run results (lab VM) and failure classification
A2: Only runs observed on the lab VM are recorded. Offline dry-runs against a mock application are NOT evidence about the application and are not listed.
A4: Run | B4: When | C4: Scope | D4: Code under test | E4: Total | F4: Passed | G4: Failed | H4: Skipped | I4: Pass rate | J4: Duration (min) | K4: Notes | L4: Itemised Passed (formula) | M4: Itemised Failed (formula)
A5: RUN-1 | B5: 2026-10-26 11:38 | C5: Smoke (@smoke), chromium + api | D5: Merged repo v1 (guessed selectors, no Create Draft step) | E5: 15 | F5: 5 | G5: 10 | H5: 0 | I5: =IF(E5=0,"n/a",F5/E5) | J5: 3.6 | K5: Failures are automation defects (see Defect Log AD-01..AD-04). Login and dashboard were correct. | L5: =COUNTIF('Test Cases'!$AB$5:$AB$110,"Passed") | M5: =COUNTIF('Test Cases'!$AB$5:$AB$110,"Failed")
A6: RUN-2 | B6: 2026-10-26 11:51 | C6: Full suite | D6: Merged repo v1 (same code as RUN-1) | E6: 96 | F6: 10 | G6: 73 | H6: 13 | I6: =IF(E6=0,"n/a",F6/E6) | J6: 14.1 | K6: Passed: AUTH-V01/V02/V03/V05/V11/V14 and FW-01..04. AUTH-V04 and DASH-V01 passed in RUN-1 but are not in RUN-2's passed list - failure text not captured (see AD-11). | L6: =COUNTIF('Test Cases'!$AC$5:$AC$110,"Passed") | M6: =COUNTIF('Test Cases'!$AC$5:$AC$110,"Failed")
A7: RUN-3 | B7: 2026-10-26 (after fixes) | C7: Smoke (@smoke), chromium + api | D7: Merged repo v2 (real ids, Create Draft step, learner account) | E7: 15 | F7: 7 | G7: 8 | H7: 0 | I7: =IF(E7=0,"n/a",F7/E7) | J7: 3.7 | K7: CLI-V01 and PROD-V01 now pass, so the Create Draft step and the client/address/KYC/product ids work live. Remaining failures: product minimum (AD-09), API 404 (AD-11), first-login timeout (AD-10). | L7: =COUNTIF('Test Cases'!$AD$5:$AD$110,"Passed") | M7: =COUNTIF('Test Cases'!$AD$5:$AD$110,"Failed")
A8: RUN-4 | B8: 2026-10-28 (after product / timeout / API-skip fixes) | C8: Smoke (@smoke), chromium + api | D8: Merged repo v3 | E8: 15 | F8: 11 | G8: 2 | H8: 2 | I8: =IF(E8=0,"n/a",F8/E8) | J8: 2.5 | K8: End-to-end submission (WF-V03), draft save (WF-V01), beneficiaries, documents and client info pass live. Failures: WF-V08 (over-specified review check, AD-12) and RIDER-V01 (premium summary not read, AD-13). API-V01/V02 skipped as an environment issue (AD-11). The review shows Calculated Age 36 for a DOB 35 years back (AC-04). | L8: =COUNTIF('Test Cases'!$AE$5:$AE$110,"Passed") | M8: =COUNTIF('Test Cases'!$AE$5:$AE$110,"Failed")
A9: RUN-5 | B9: 2026-10-28 (after the WF-V08 / CLI-V13 / diagnostics patch) | C9: Smoke (@smoke), chromium + api | D9: Merged repo v4 | E9: 15 | F9: 12 | G9: 1 | H9: 2 | I9: =IF(E9=0,"n/a",F9/E9) | J9: 2 | K9: Only RIDER-V01 fails: the page shows "Current rider premium: $0.00" until the step is saved (AD-13). API-V01/V02 still skipped (AD-11). CLI-V13 (age) not yet run. | L9: =COUNTIF('Test Cases'!$AF$5:$AF$110,"Passed") | M9: =COUNTIF('Test Cases'!$AF$5:$AF$110,"Failed")
A11: Classification of the failures (from the Defect Log)
A12: Type | B12: Count | C12: Meaning
A13: Automation defect | B13: =COUNTIF('Defect Log'!$B$5:$B$24,A13) | C13: The test or page object was wrong (locator, flow, API contract).
A14: Test-data issue | B14: =COUNTIF('Defect Log'!$B$5:$B$24,A14) | C14: Data or account choice made a correct test fail.
A15: Environment issue | B15: =COUNTIF('Defect Log'!$B$5:$B$24,A15) | C15: Lab VM, URL, port or timing - not a product defect.
A16: Application defect (candidate) | B16: =COUNTIF('Defect Log'!$B$5:$B$24,A16) | C16: Possible application defect, NOT yet reproduced on the lab.
A17: Clarification | B17: =COUNTIF('Defect Log'!$B$5:$B$24,A17) | C17: Needs a product-owner answer before it can be called a defect.
A18: Confirmed application defects | B18: =COUNTIFS('Defect Log'!$B$5:$B$24,"Application defect*",'Defect Log'!$K$5:$K$24,"Confirmed*") | C18: None yet: the live runs so far failed before any validation rule was reached. Re-run after the fixes, then update this sheet.

Sheet Defect Log
